<?xml version="1.0"?>
<robot xmlns:xacro="http://www.ros.org/wiki/xacro">

  <xacro:include filename="$(find precise_description)/urdf/transmission.xacro" />

  <xacro:macro name="precise_flex" params="parent name *origin has_podest:=True">

    <xacro:property name="origin_1_joint">
      <origin xyz="${robot_properties['arm']['arm_1_joint']['origin']['x']} ${robot_properties['arm']['arm_1_joint']['origin']['y']} ${robot_properties['arm']['arm_1_joint']['origin']['z']}" rpy="${robot_properties['arm']['arm_1_joint']['origin']['roll']} ${robot_properties['arm']['arm_1_joint']['origin']['pitch']} ${robot_properties['arm']['arm_1_joint']['origin']['yaw']}"/>
    </xacro:property>
    <xacro:property name="origin_2_joint">
      <origin xyz="${robot_properties['arm']['arm_2_joint']['origin']['x']} ${robot_properties['arm']['arm_2_joint']['origin']['y']} ${robot_properties['arm']['arm_2_joint']['origin']['z']}" rpy="${robot_properties['arm']['arm_2_joint']['origin']['roll']} ${robot_properties['arm']['arm_2_joint']['origin']['pitch']} ${robot_properties['arm']['arm_2_joint']['origin']['yaw']}"/>
    </xacro:property>
    <xacro:property name="origin_3_joint">
      <origin xyz="${robot_properties['arm']['arm_3_joint']['origin']['x']} ${robot_properties['arm']['arm_3_joint']['origin']['y']} ${robot_properties['arm']['arm_3_joint']['origin']['z']}" rpy="${robot_properties['arm']['arm_3_joint']['origin']['roll']} ${robot_properties['arm']['arm_3_joint']['origin']['pitch']} ${robot_properties['arm']['arm_3_joint']['origin']['yaw']}"/>
    </xacro:property>
    <xacro:property name="origin_4_joint">
      <origin xyz="${robot_properties['arm']['arm_4_joint']['origin']['x']} ${robot_properties['arm']['arm_4_joint']['origin']['y']} ${robot_properties['arm']['arm_4_joint']['origin']['z']}" rpy="${robot_properties['arm']['arm_4_joint']['origin']['roll']} ${robot_properties['arm']['arm_4_joint']['origin']['pitch']} ${robot_properties['arm']['arm_4_joint']['origin']['yaw']}"/>
    </xacro:property>
    <xacro:property name="origin_5_joint">
      <origin xyz="${robot_properties['arm']['arm_5_joint']['origin']['x']} ${robot_properties['arm']['arm_5_joint']['origin']['y']} ${robot_properties['arm']['arm_5_joint']['origin']['z']}" rpy="${robot_properties['arm']['arm_5_joint']['origin']['roll']} ${robot_properties['arm']['arm_5_joint']['origin']['pitch']} ${robot_properties['arm']['arm_5_joint']['origin']['yaw']}"/>
    </xacro:property>
    <xacro:property name="origin_ee_joint">
      <origin xyz="${robot_properties['arm']['arm_ee_joint']['origin']['x']} ${robot_properties['arm']['arm_ee_joint']['origin']['y']} ${robot_properties['arm']['arm_ee_joint']['origin']['z']}" rpy="${robot_properties['arm']['arm_ee_joint']['origin']['roll']} ${robot_properties['arm']['arm_ee_joint']['origin']['pitch']} ${robot_properties['arm']['arm_ee_joint']['origin']['yaw']}"/>
    </xacro:property>
    <xacro:property name="origin_gripper_ee_fixed_joint">
      <origin xyz="${robot_properties['arm']['gripper_ee_fixed_joint']['origin']['x']} ${robot_properties['arm']['gripper_ee_fixed_joint']['origin']['y']} ${robot_properties['arm']['gripper_ee_fixed_joint']['origin']['z']}" rpy="${robot_properties['arm']['gripper_ee_fixed_joint']['origin']['roll']} ${robot_properties['arm']['gripper_ee_fixed_joint']['origin']['pitch']} ${robot_properties['arm']['gripper_ee_fixed_joint']['origin']['yaw']}"/>
    </xacro:property>
    <xacro:property name="origin_gripper_ee_joint">
      <origin xyz="${robot_properties['arm']['gripper_ee_joint']['origin']['x']} ${robot_properties['arm']['gripper_ee_joint']['origin']['y']} ${robot_properties['arm']['gripper_ee_joint']['origin']['z']}" rpy="${robot_properties['arm']['gripper_ee_joint']['origin']['roll']} ${robot_properties['arm']['gripper_ee_joint']['origin']['pitch']} ${robot_properties['arm']['gripper_ee_joint']['origin']['yaw']}"/>
    </xacro:property>

    <xacro:property name="limit_1_joint">
      <limit effort="${robot_properties['arm']['arm_1_joint']['limit']['effort']}" lower="${robot_properties['arm']['arm_1_joint']['limit']['lower']}" upper="${robot_properties['arm']['arm_1_joint']['limit']['upper']}" velocity="${robot_properties['arm']['arm_1_joint']['limit']['velocity']}"/>
    </xacro:property>
    <xacro:property name="limit_2_joint">
      <limit effort="${robot_properties['arm']['arm_2_joint']['limit']['effort']}" lower="${robot_properties['arm']['arm_2_joint']['limit']['lower']}" upper="${robot_properties['arm']['arm_2_joint']['limit']['upper']}" velocity="${robot_properties['arm']['arm_2_joint']['limit']['velocity']}"/>
    </xacro:property>
    <xacro:property name="limit_3_joint">
      <limit effort="${robot_properties['arm']['arm_3_joint']['limit']['effort']}" lower="${robot_properties['arm']['arm_3_joint']['limit']['lower']}" upper="${robot_properties['arm']['arm_3_joint']['limit']['upper']}" velocity="${robot_properties['arm']['arm_3_joint']['limit']['velocity']}"/>
    </xacro:property>
    <xacro:property name="limit_4_joint">
      <limit effort="${robot_properties['arm']['arm_4_joint']['limit']['effort']}" lower="${robot_properties['arm']['arm_4_joint']['limit']['lower']}" upper="${robot_properties['arm']['arm_4_joint']['limit']['upper']}" velocity="${robot_properties['arm']['arm_4_joint']['limit']['velocity']}"/>
    </xacro:property>
    <xacro:property name="limit_5_joint">
      <limit effort="${robot_properties['arm']['arm_5_joint']['limit']['effort']}" lower="${robot_properties['arm']['arm_5_joint']['limit']['lower']}" upper="${robot_properties['arm']['arm_5_joint']['limit']['upper']}" velocity="${robot_properties['arm']['arm_5_joint']['limit']['velocity']}"/>
    </xacro:property>

    <material name="precise_white">
      <color rgba="1 1 1 1"/>
    </material>

    <!-- mounting -->
    <joint name="${name}_base_joint" type="fixed">
      <xacro:insert_block name="origin" />
      <parent link="${parent}"/>
      <child link="${name}_base_link" />
    </joint>
    <link name="${name}_base_link">
      <xacro:default_inertial/>
    </link>
    <joint name="${name}_mount_joint" type="fixed">
      <origin xyz="0 0 0" rpy="0 0 0"/>
      <parent link="${name}_base_link"/>
      <child link="${name}_1_link"/>
    </joint>

    <xacro:if value="${has_podest}">
      <joint name="${name}_podest_joint" type="fixed">
        <origin xyz="0 0 -0.0096" rpy="0 0 0"/>
        <parent link="${name}_base_link"/>
        <child link="${name}_podest_link"/>
      </joint>
      <link name="${name}_podest_link">
        <xacro:default_inertial/>
        <visual>
          <origin xyz="0 0 0" rpy="0 0 0" />
          <geometry>
            <mesh filename="${robot_properties['arm']['arm_podest_link']['visual_mesh']}"/>
          </geometry>
        </visual>
        <collision>
          <origin xyz="0 0 0" rpy="0 0 0" />
          <geometry>
            <mesh filename="${robot_properties['arm']['arm_podest_link']['visual_mesh']}"/>
          </geometry>
        </collision>
      </link>
    </xacro:if>


    <!-- Links -->
    <link name="${name}_1_link">
      <xacro:default_inertial/>
      <visual>
        <origin xyz="0 0 0" rpy="0 0 0"/>
        <geometry>
          <mesh filename="${robot_properties['arm']['arm_1_link']['visual_mesh']}"/>
        </geometry>
        <material name="precise_white"/>
      </visual>
      <collision>
        <origin xyz="0 0 0" rpy="0 0 0"/>
        <geometry>
          <mesh filename="${robot_properties['arm']['arm_1_link']['visual_mesh']}"/>
        </geometry>
        <material name="precise_white"/>
      </collision>
    </link>

    <link name="${name}_2_link">
      <xacro:default_inertial/>
      <visual>
        <origin xyz="0 0 0" rpy="0 0 0"/>
        <geometry>
          <mesh filename="${robot_properties['arm']['arm_2_link']['visual_mesh']}"/>
        </geometry>
        <material name="precise_white"/>
      </visual>
      <collision>
        <origin xyz="0 0 0" rpy="0 0 0"/>
        <geometry>
          <mesh filename="${robot_properties['arm']['arm_2_link']['visual_mesh']}"/>
        </geometry>
        <material name="precise_white"/>
      </collision>
    </link>

    <link name="${name}_3_link">
      <xacro:default_inertial/>
      <visual>
        <origin xyz="0 0 0" rpy="0 0 0"/>
        <geometry>
          <mesh filename="${robot_properties['arm']['arm_3_link']['visual_mesh']}"/>
        </geometry>
        <material name="precise_white"/>
      </visual>
      <collision>
        <origin xyz="0 0 0" rpy="0 0 0"/>
        <geometry>
          <mesh filename="${robot_properties['arm']['arm_3_link']['visual_mesh']}"/>
        </geometry>
        <material name="precise_white"/>
      </collision>
    </link>

    <link name="${name}_4_link">
      <xacro:default_inertial/>
      <visual>
        <origin xyz="0 0 0" rpy="0 0 0"/>
        <geometry>
          <mesh filename="${robot_properties['arm']['arm_4_link']['visual_mesh']}"/>
        </geometry>
        <material name="precise_white"/>
      </visual>
      <collision>
        <origin xyz="0 0 0" rpy="0 0 0"/>
        <geometry>
          <mesh filename="${robot_properties['arm']['arm_4_link']['visual_mesh']}"/>
        </geometry>
        <material name="precise_white"/>
      </collision>
    </link>

    <link name="${name}_5_link">
      <xacro:default_inertial/>
      <visual>
        <origin xyz="0 0 0" rpy="0 0 0"/>
        <geometry>
          <mesh filename="${robot_properties['arm']['arm_5_link']['visual_mesh']}"/>
        </geometry>
        <material name="precise_white"/>
      </visual>
      <collision>
        <origin xyz="0 0 0" rpy="0 0 0"/>
        <geometry>
          <mesh filename="${robot_properties['arm']['arm_5_link']['visual_mesh']}"/>
        </geometry>
        <material name="precise_white"/>
      </collision>
    </link>

    <link name="${name}_left_finger_mount_link">
      <xacro:default_inertial/>
    </link>

    <link name="${name}_right_finger_mount_link">
      <xacro:default_inertial/>
    </link>

    <!-- Joints -->
    <joint name="${name}_1_joint" type="prismatic">
      <parent link="${name}_1_link"/>
      <child link="${name}_2_link"/>
      <axis xyz="0 0 1"/>
      <xacro:insert_block name="origin_1_joint"/>
      <xacro:insert_block name="limit_1_joint"/>
    </joint>

    <joint name="${name}_2_joint" type="revolute">
      <parent link="${name}_2_link"/>
      <child link="${name}_3_link"/>
      <axis xyz="0 0 1"/>
      <xacro:insert_block name="origin_2_joint"/>
      <xacro:insert_block name="limit_2_joint"/>
    </joint>

    <joint name="${name}_3_joint" type="revolute">
      <parent link="${name}_3_link"/>
      <child link="${name}_4_link"/>
      <axis xyz="0 0 1"/>
      <xacro:insert_block name="origin_3_joint"/>
      <xacro:insert_block name="limit_3_joint"/>
    </joint>

    <joint name="${name}_4_joint" type="revolute">
      <parent link="${name}_4_link"/>
      <child link="${name}_5_link"/>
      <axis xyz="0 0 1"/>
      <xacro:insert_block name="origin_4_joint"/>
      <xacro:insert_block name="limit_4_joint"/>
    </joint>

    <joint name="${name}_5_joint" type="prismatic">
      <parent link="${name}_5_link"/>
      <child link="${name}_left_finger_mount_link"/>
      <axis xyz="0 1 0"/>
      <xacro:insert_block name="origin_5_joint"/>
      <xacro:insert_block name="limit_5_joint"/>
    </joint>

    <joint name="${name}_5_mimic_joint" type="prismatic">
      <parent link="${name}_5_link"/>
      <child link="${name}_right_finger_mount_link"/>
      <axis xyz="0 -1 0"/>
      <xacro:insert_block name="origin_5_joint"/>
      <xacro:insert_block name="limit_5_joint"/>
      <mimic joint="${name}_5_joint" multiplier="1"/>
    </joint>
    <gazebo>
      <plugin name="${name}_5_mimic_joint_gazebo" filename="libgazebo_ros_mimic_joint.so">
        <jointName>${name}_5_mimic_joint</jointName>
        <mimicJoint>${name}_5_joint</mimicJoint>
        <multiplier>1.0</multiplier>
        <offset>0.0</offset>
      </plugin>
    </gazebo>

    <!-- endeffector -->
    <joint name="${name}_ee_joint" type="fixed">
      <xacro:insert_block name="origin_ee_joint"/>
      <parent link="${name}_5_link"/>
      <child link="${name}_ee_link" />
    </joint>
    <link name="${name}_ee_link">
      <xacro:default_inertial/>
    </link>

    <!-- extensions -->
    <xacro:precise_flex_transmission name="${name}"/>

    <!-- ros_control plugin -->
    <gazebo>
      <plugin name="${name}_ros_control" filename="libhwi_switch_gazebo_ros_control.so">
        <robotNamespace>${name}</robotNamespace>
        <filterJointsParam>joint_names</filterJointsParam>
      </plugin>
    </gazebo>

  </xacro:macro>

</robot>
